{
 "cells": [
  {
   "cell_type": "code",
   "execution_count": 1,
   "metadata": {},
   "outputs": [],
   "source": [
    "import seaborn as sns\n",
    "import matplotlib.pyplot as plt\n",
    "sns.set_theme(style='ticks', color_codes=True)\n"
   ]
  },
  {
   "cell_type": "code",
   "execution_count": 4,
   "metadata": {},
   "outputs": [
    {
     "ename": "URLError",
     "evalue": "<urlopen error [Errno 11001] getaddrinfo failed>",
     "output_type": "error",
     "traceback": [
      "\u001b[1;31m---------------------------------------------------------------------------\u001b[0m",
      "\u001b[1;31mgaierror\u001b[0m                                  Traceback (most recent call last)",
      "\u001b[1;32mH:\\Data science\\Pyton ka chilla\\Python ka chill\\lib\\urllib\\request.py\u001b[0m in \u001b[0;36mdo_open\u001b[1;34m(self, http_class, req, **http_conn_args)\u001b[0m\n",
      "\u001b[1;32mH:\\Data science\\Pyton ka chilla\\Python ka chill\\lib\\http\\client.py\u001b[0m in \u001b[0;36mrequest\u001b[1;34m(self, method, url, body, headers, encode_chunked)\u001b[0m\n",
      "\u001b[1;32mH:\\Data science\\Pyton ka chilla\\Python ka chill\\lib\\http\\client.py\u001b[0m in \u001b[0;36m_send_request\u001b[1;34m(self, method, url, body, headers, encode_chunked)\u001b[0m\n",
      "\u001b[1;32mH:\\Data science\\Pyton ka chilla\\Python ka chill\\lib\\http\\client.py\u001b[0m in \u001b[0;36mendheaders\u001b[1;34m(self, message_body, encode_chunked)\u001b[0m\n",
      "\u001b[1;32mH:\\Data science\\Pyton ka chilla\\Python ka chill\\lib\\http\\client.py\u001b[0m in \u001b[0;36m_send_output\u001b[1;34m(self, message_body, encode_chunked)\u001b[0m\n",
      "\u001b[1;32mH:\\Data science\\Pyton ka chilla\\Python ka chill\\lib\\http\\client.py\u001b[0m in \u001b[0;36msend\u001b[1;34m(self, data)\u001b[0m\n",
      "\u001b[1;32mH:\\Data science\\Pyton ka chilla\\Python ka chill\\lib\\http\\client.py\u001b[0m in \u001b[0;36mconnect\u001b[1;34m(self)\u001b[0m\n",
      "\u001b[1;32mH:\\Data science\\Pyton ka chilla\\Python ka chill\\lib\\http\\client.py\u001b[0m in \u001b[0;36mconnect\u001b[1;34m(self)\u001b[0m\n",
      "\u001b[1;32mH:\\Data science\\Pyton ka chilla\\Python ka chill\\lib\\socket.py\u001b[0m in \u001b[0;36mcreate_connection\u001b[1;34m(address, timeout, source_address)\u001b[0m\n",
      "\u001b[1;32mH:\\Data science\\Pyton ka chilla\\Python ka chill\\lib\\socket.py\u001b[0m in \u001b[0;36mgetaddrinfo\u001b[1;34m(host, port, family, type, proto, flags)\u001b[0m\n",
      "\u001b[1;31mgaierror\u001b[0m: [Errno 11001] getaddrinfo failed",
      "\nDuring handling of the above exception, another exception occurred:\n",
      "\u001b[1;31mURLError\u001b[0m                                  Traceback (most recent call last)",
      "\u001b[1;32m<ipython-input-4-b1fb70a56dd5>\u001b[0m in \u001b[0;36m<module>\u001b[1;34m\u001b[0m\n\u001b[1;32m----> 1\u001b[1;33m \u001b[0mtitanic\u001b[0m \u001b[1;33m=\u001b[0m \u001b[0msns\u001b[0m\u001b[1;33m.\u001b[0m\u001b[0mload_dataset\u001b[0m\u001b[1;33m(\u001b[0m\u001b[1;34m\"titanic\"\u001b[0m\u001b[1;33m)\u001b[0m\u001b[1;33m\u001b[0m\u001b[1;33m\u001b[0m\u001b[0m\n\u001b[0m",
      "\u001b[1;32mH:\\Data science\\Pyton ka chilla\\Python ka chill\\lib\\site-packages\\seaborn\\utils.py\u001b[0m in \u001b[0;36mload_dataset\u001b[1;34m(name, cache, data_home, **kws)\u001b[0m\n",
      "\u001b[1;32mH:\\Data science\\Pyton ka chilla\\Python ka chill\\lib\\site-packages\\seaborn\\utils.py\u001b[0m in \u001b[0;36mget_dataset_names\u001b[1;34m()\u001b[0m\n",
      "\u001b[1;32mH:\\Data science\\Pyton ka chilla\\Python ka chill\\lib\\urllib\\request.py\u001b[0m in \u001b[0;36murlopen\u001b[1;34m(url, data, timeout, cafile, capath, cadefault, context)\u001b[0m\n",
      "\u001b[1;32mH:\\Data science\\Pyton ka chilla\\Python ka chill\\lib\\urllib\\request.py\u001b[0m in \u001b[0;36mopen\u001b[1;34m(self, fullurl, data, timeout)\u001b[0m\n",
      "\u001b[1;32mH:\\Data science\\Pyton ka chilla\\Python ka chill\\lib\\urllib\\request.py\u001b[0m in \u001b[0;36m_open\u001b[1;34m(self, req, data)\u001b[0m\n",
      "\u001b[1;32mH:\\Data science\\Pyton ka chilla\\Python ka chill\\lib\\urllib\\request.py\u001b[0m in \u001b[0;36m_call_chain\u001b[1;34m(self, chain, kind, meth_name, *args)\u001b[0m\n",
      "\u001b[1;32mH:\\Data science\\Pyton ka chilla\\Python ka chill\\lib\\urllib\\request.py\u001b[0m in \u001b[0;36mhttps_open\u001b[1;34m(self, req)\u001b[0m\n",
      "\u001b[1;32mH:\\Data science\\Pyton ka chilla\\Python ka chill\\lib\\urllib\\request.py\u001b[0m in \u001b[0;36mdo_open\u001b[1;34m(self, http_class, req, **http_conn_args)\u001b[0m\n",
      "\u001b[1;31mURLError\u001b[0m: <urlopen error [Errno 11001] getaddrinfo failed>"
     ]
    }
   ],
   "source": [
    "titanic = sns.load_dataset(\"titanic\")"
   ]
  },
  {
   "cell_type": "code",
   "execution_count": null,
   "metadata": {},
   "outputs": [],
   "source": []
  }
 ],
 "metadata": {
  "kernelspec": {
   "display_name": "Python 3",
   "language": "python",
   "name": "python3"
  },
  "language_info": {
   "codemirror_mode": {
    "name": "ipython",
    "version": 3
   },
   "file_extension": ".py",
   "mimetype": "text/x-python",
   "name": "python",
   "nbconvert_exporter": "python",
   "pygments_lexer": "ipython3",
   "version": "3.8.5"
  }
 },
 "nbformat": 4,
 "nbformat_minor": 4
}
